Workbook
Name aaaa: #REF!
Name erwer: #REF!
Name ListCapaSource: #REF!
Name ListCapaSp: [1]Lists!#REF!
Name ListCapaSponsor: #REF!
Name ListDocStatus: #REF!
Name ListDocumentStatus: [2]List!$A$2:$A$6
Name ListYN: #REF!
Name test: #REF!
Name x: [3]List!$A$2:$A$6

Sheet STET_GB_2026 Competency Ratings
D3: 2024 Baseline | E3: 2025 Baseline | F3: H1'26 Target | G3: H1'26 Actual | H3: H2'26 Target | I3: H2'26 Actual
B4: LEVEL-4 | C4: Master | D4: =PL!AE4+ME!AC4+PE!AD4+EE!AE4+QPL!AE4+SE!AE4+TPD!AE4+'T&V'!AE4 -> 0 | E4: =PL!AF4+ME!AD4+PE!AE4+EE!AF4+QPL!AF4+SE!AF4+TPD!AF4+'T&V'!AF4 -> 38 | F4: =PL!AG4+ME!AE4+PE!AF4+EE!AG4+QPL!AG4+SE!AG4+TPD!AG4+'T&V'!AG4 -> 16 | G4: =PL!AH4+ME!AF4+PE!AG4+EE!AH4+QPL!AH4+SE!AH4+TPD!AH4+'T&V'!AH4 -> 0 | H4: =PL!AI4+ME!AG4+PE!AH4+EE!AI4+QPL!AI4+SE!AI4+TPD!AI4+'T&V'!AI4 -> 32 | I4: =PL!AJ4+ME!AH4+PE!AI4+EE!AJ4+QPL!AJ4+SE!AJ4+TPD!AJ4+'T&V'!AJ4 -> 0
B5: LEVEL-3 | C5: Expert | D5: =PL!AE5+ME!AC5+PE!AD5+EE!AE5+QPL!AE5+SE!AE5+TPD!AE5+'T&V'!AE5 -> 44 | E5: =PL!AF5+ME!AD5+PE!AE5+EE!AF5+QPL!AF5+SE!AF5+TPD!AF5+'T&V'!AF5 -> 120 | F5: =PL!AG5+ME!AE5+PE!AF5+EE!AG5+QPL!AG5+SE!AG5+TPD!AG5+'T&V'!AG5 -> 108 | G5: =PL!AH5+ME!AF5+PE!AG5+EE!AH5+QPL!AH5+SE!AH5+TPD!AH5+'T&V'!AH5 -> 0 | H5: =PL!AI5+ME!AG5+PE!AH5+EE!AI5+QPL!AI5+SE!AI5+TPD!AI5+'T&V'!AI5 -> 175 | I5: =PL!AJ5+ME!AH5+PE!AI5+EE!AJ5+QPL!AJ5+SE!AJ5+TPD!AJ5+'T&V'!AJ5 -> 0
B6: LEVEL-2 | C6: Practitioner | D6: =PL!AE6+ME!AC6+PE!AD6+EE!AE6+QPL!AE6+SE!AE6+TPD!AE6+'T&V'!AE6 -> 144 | E6: =PL!AF6+ME!AD6+PE!AE6+EE!AF6+QPL!AF6+SE!AF6+TPD!AF6+'T&V'!AF6 -> 276 | F6: =PL!AG6+ME!AE6+PE!AF6+EE!AG6+QPL!AG6+SE!AG6+TPD!AG6+'T&V'!AG6 -> 245 | G6: =PL!AH6+ME!AF6+PE!AG6+EE!AH6+QPL!AH6+SE!AH6+TPD!AH6+'T&V'!AH6 -> 0 | H6: =PL!AI6+ME!AG6+PE!AH6+EE!AI6+QPL!AI6+SE!AI6+TPD!AI6+'T&V'!AI6 -> 390 | I6: =PL!AJ6+ME!AH6+PE!AI6+EE!AJ6+QPL!AJ6+SE!AJ6+TPD!AJ6+'T&V'!AJ6 -> 0
B7: LEVEL-1 | C7: Foundation | D7: =PL!AE7+ME!AC7+PE!AD7+EE!AE7+QPL!AE7+SE!AE7+TPD!AE7+'T&V'!AE7 -> 99 | E7: =PL!AF7+ME!AD7+PE!AE7+EE!AF7+QPL!AF7+SE!AF7+TPD!AF7+'T&V'!AF7 -> 139 | F7: =PL!AG7+ME!AE7+PE!AF7+EE!AG7+QPL!AG7+SE!AG7+TPD!AG7+'T&V'!AG7 -> 174 | G7: =PL!AH7+ME!AF7+PE!AG7+EE!AH7+QPL!AH7+SE!AH7+TPD!AH7+'T&V'!AH7 -> 0 | H7: =PL!AI7+ME!AG7+PE!AH7+EE!AI7+QPL!AI7+SE!AI7+TPD!AI7+'T&V'!AI7 -> 272 | I7: =PL!AJ7+ME!AH7+PE!AI7+EE!AJ7+QPL!AJ7+SE!AJ7+TPD!AJ7+'T&V'!AJ7 -> 0
B8: LEVEL-0 | C8: Entry | D8: =PL!AE8+ME!AC8+PE!AD8+EE!AE8+QPL!AE8+SE!AE8+TPD!AE8+'T&V'!AE8 -> 43 | E8: =PL!AF8+ME!AD8+PE!AE8+EE!AF8+QPL!AF8+SE!AF8+TPD!AF8+'T&V'!AF8 -> 43 | F8: =PL!AG8+ME!AE8+PE!AF8+EE!AG8+QPL!AG8+SE!AG8+TPD!AG8+'T&V'!AG8 -> 8 | G8: =PL!AH8+ME!AF8+PE!AG8+EE!AH8+QPL!AH8+SE!AH8+TPD!AH8+'T&V'!AH8 -> 0 | H8: =PL!AI8+ME!AG8+PE!AH8+EE!AI8+QPL!AI8+SE!AI8+TPD!AI8+'T&V'!AI8 -> 18 | I8: =PL!AJ8+ME!AH8+PE!AI8+EE!AJ8+QPL!AJ8+SE!AJ8+TPD!AJ8+'T&V'!AJ8 -> 0
D9: =SUM(D4:D8) -> 330 | E9: =SUM(E4:E8) -> 616 | F9: =SUM(F4:F8) -> 551 | G9: =SUM(G4:G8) -> 0 | H9: =SUM(H4:H8) -> 887 | I9: =SUM(I4:I8) -> 0
D11: =D3 -> 2024 Baseline | E11: =E3 -> 2025 Baseline | F11: =F3 -> H1'26 Target | G11: =G3 -> H1'26 Actual | H11: =H3 -> H2'26 Target | I11: =I3 -> H2'26 Actual
B12: LEVEL-4 | C12: Master | D12: =$D4/$D$9 -> 0 | E12: =$E4/$E$9 -> 0.061688312 | F12: =$F4/$F$9 -> 0.029038113 | G12: =$D4/$D9 -> 0 | H12: =$H4/$H$9 -> 0.036076663 | I12: =$D4/$D9 -> 0
B13: LEVEL-3 | C13: Expert | D13: =$D5/$D$9 -> 0.13333333 | E13: =$E5/$E$9 -> 0.19480519 | F13: =$F5/$F$9 -> 0.19600726 | H13: =$H5/$H$9 -> 0.19729425
B14: LEVEL-2 | C14: Practitioner | D14: =$D6/$D$9 -> 0.43636364 | E14: =$E6/$E$9 -> 0.44805195 | F14: =$F6/$F$9 -> 0.4446461 | H14: =$H6/$H$9 -> 0.43968433
B15: LEVEL-1 | C15: Foundation | D15: =$D7/$D$9 -> 0.3 | E15: =$E7/$E$9 -> 0.22564935 | F15: =$F7/$F$9 -> 0.31578947 | H15: =$H7/$H$9 -> 0.30665163
B16: LEVEL-0 | C16: Entry | D16: =$D8/$D$9 -> 0.13030303 | E16: =$E8/$E$9 -> 0.069805195 | F16: =$F8/$F$9 -> 0.014519056 | H16: =$H8/$H$9 -> 0.020293123
D17: =SUM(D12:D16) -> 1 | E17: =SUM(E12:E16) -> 1 | F17: =SUM(F12:F16) -> 1 | G17: =SUM(G12:G16) -> 0 | H17: =SUM(H12:H16) -> 1 | I17: =SUM(I12:I16) -> 0
B19: 2026 Goal | D19: 0.7
B20: YTD
B21: H1'2026 Target | D21: =H12+H13+H14 -> 0.67305524
B22: Gap to Goal | D22: =D19-D21 -> 0.026944758

Sheet Competence definitions
C2: Competence Framework
B4: Team | C4: Core Curriculum Skills | D4: Description
B5: T&V | C5: Development Logic | D5: Understanding the flow of the full development logic from VPC start untill PDLM-End based on Systems Engineering, supported by MBSE. Ability to create a high level (model-Based) Systems. Understand the steps in the E2E development logic based on the v-model grid and how these steps are linked. Ability to identify development challenges in an early stage of the project to prevent rework in late stage of the project.
B6: T&V | C6: Product Safety Risk Management | D6: Able to apply, in collaboration with product safety risk specialists if applicable, risk management methodologies specifically related to product safety, including e.g. FMEA, Hazard Based Safety Risk Assessments, feeding back Post Market Surveillance inputs, and distinguishing between hazard, harm and risk and applying the appropriate risk reduction and control measures, complying with all relevant standards (e.g. ISO14971) determined by (local) Q&R.
B7: T&V | C7: System engineering/ Requirement management | D7: Able to effectively use set of techniques for documenting, analyzing, prioritizing and agreeing on requirements in a clear, concise, error-free way. Ability to meet user needs by a structured development approach based on requirements engineering. Managing complexity of systems by proper system decomposition and interface control. Qualitatatively underpinning design decision by applying modeling and simulation techniques.
B8: T&V | C8: Product Architecture | D8: Able to organize and integrate product functions and features, and the way in which those interact. Understanding how users will interact with the product, including navigatibg around the product and performing actions, where the data comes from, and what technology supports this infrastucture.
B9: T&V | C9: PDLM process | D9: Understanding how PDLM is pat of PEPF and how the full process model impacts the customer. Understanding how PDLM fits into I2M process logic. Able to effecively use the process in a structured way to ensure design have been properly developped and documented in accordance with the requirements and applicable regulations. Able to apply PDLM adoption rules during product development, understanding gate governance and effective navigation within the process framework.
B10: T&V | C10: MBSE | D10: Able to effectively build, improve and use fomalized methodology that is used to support requirements, design, analysis, verification and validation associated with the development of complex systems. Able to adopt digital- modeling environment to manage the data.
B11: T&V | C11: Change Control | D11: Understanding how organization manages modification of the design and processes. Understanding how to ensure quality and regulator requirements are met in design change/ process change. Able to manage desig changes.
B12: T&V | C12: Standards & Regulations; QMS | D12: Able to analyze, interpret and apply all relevant standards and regulations as considered applicable by Q&R, including global, local and internal Philips standards and regulations, such as to ensure regulatory compliance in the design; able to understand how quality standards and regulations are integrated into applicable QMS
B13: T&V | C13: DFSS | D13: Able to effectovely deploy DfSS mothododlogy in order to develop new products and solutions. The DfSS methodology encompasses a big framework of methods and tools, based on groups of activities that are common in developing new products. DfSS focus is on identifying CTQ (Critical to Quality) needs and guarding that they are fulfilled by the design.
B14: T&V | C14: Red X | D14: Able to apply Red X mothodology in order to solve problems in structured and logic way.
B15: T&V | C15: Functional Skills | D15: Description
... B57: SE | C57: Technical root cause analysis | D57: ability to apply structured methodologies such as Red X and DfSS (Design for Six Sigma) to systematically identify, analyze, and resolve complex technical issues. These approaches emphasize logical, stepwise investigation to isolate root causes and implement effective solutions. Demonstrate familiarity with statistical software and the ability to interpret quantitative data are essential for substantiating findings and validating corrective actions.
B58: SE | C58: Technical problem solving
B59: SE | C59: Change management (impact analysis and implementation) | D59: Ability to effectively manage changes to product designs, specifications, or production processes throughout the product lifecycle. This includes planning, implementing, and monitoring these changes while minimizing disruption, reducing errors, and improving product quality. It also involves building a culture of continuous improvement and adaptation within the product team
B60: SE | C60: Good documentation practice | D60: Provide a consistent set of supporting requirements for Documented Information to ensure documentation is clear, concise, correct, complete and traceable. The application of GDP will help to reduce misinterpretations and errors.
B61: SE | C61: Structured way of product development (specification and verification according to V-model)
B62: SE | C62: Domain / Technical expertise
B63: SE | C63: (Soft) Human Skills | D63: Description
B64: SE | C64: Stakeholder Communication | D64: Identify various types of stakeholders. Evaluate the roles of stakeholders and determine their communication and support requirements. Recognize conflicts and employ appropriate conflict resolution strategies. Develop change management plans aligned with stakeholder needs.
B65: SE | C65: Presentation Skills : ( Articulation and ability to communicate)
B66: SE | C66: Ownership and Accountability (Say Do Ratio) | D66: Ownership is when someone takes responsibility for a task and feels the intrinsic motivation to follow up and follow through. Accountability in the office is about clearly identifying the company’s vision, values, and goals and holding individuals to them. Employee accountability is holding all levels of employees accountable for meeting corporate objectives.
B67: SE | C67: Assertiveness
B68: TPD | C68: Process Skills | D68: Description
B69: TPD | C69: TPD Basic Understanding
B70: TPD | C70: Windchill Competency
B71: TPD | C71: Change Request Knowledge
B72: TPD | C72: Materials Knowledge
B73: TPD | C73: CAD Skills
B74: TPD | C74: Configuration management
B75: TPD | C75: Typeplates
B76: TPD | C76: Pkg & Sustainability
B77: TPD | C77: EPR / CSRD
B78: TPD | C78: Service Planner
B79: TPD | C79: Refurbishment Planner
B80: TPD | C80: (Soft) Human Skills | D80: Description
B81: TPD | C81: Stakeholder Communication | D81: Identify various types of stakeholders. Evaluate the roles of stakeholders and determine their communication and support requirements. Recognize conflicts and employ appropriate conflict resolution strategies. Develop change management plans aligned with stakeholder needs.
B82: TPD | C82: Presentation Skills : ( Articulation and ability to communicate)
B83: TPD | C83: Ownership and Accountability (Say Do Ratio) | D83: Ownership is when someone takes responsibility for a task and feels the intrinsic motivation to follow up and follow through. Accountability in the office is about clearly identifying the company’s vision, values, and goals and holding individuals to them. Employee accountability is holding all levels of employees accountable for meeting corporate objectives.
...

Sheet PL-H1
B2: STET GB Project Leader Team Competency Plan 2025
B3: STET-GB Competency Assessment 2025 | D3: G&B PL | J3: PIC | K3: IPL PL
B4: Function group | C4: Process knowledge area/ EPM skill | D4: Kirti | E4: Anjali | F4: Shiv | G4: Ashwini | H4: Rohit | I4: Mahesh | J4: Freddy | K4: Dayal | L4: Sonam | M4: Chetan | Q4: =SUM(Q5:Q9) -> 15 | R4: =SUM(R5:R9) -> 15 | S4: =SUM(S5:S9) -> 15 | T4: =SUM(T5:T9) -> 15 | U4: =SUM(U5:U9) -> 15 | V4: =SUM(V5:V9) -> 15 | W4: =SUM(W5:W9) -> 15 | X4: =SUM(X5:X9) -> 13 | ... AA4: =SUM(AA5:AA9) -> 86 | AB4: 148 | AC4: =SUM(AC5:AC9) -> 148 | AD4: 148 | AE4: =SUM(AE5:AE10) -> 0 | AG4: Rev | AH4: Date | AI4: Description | AJ4: Done by
B5: Process | C5: Market Introduction Plan/Phase-in | D5: 4 | E5: 2 | F5: 4 | G5: 3 | H5: 3 | I5: 0 | J5: 2 | K5: NA | L5: 3 | M5: 2 | O5: LEVEL-4 | P5: Master | Q5: =COUNTIF(D$5:D$19,4) -> 1 | R5: =COUNTIF(E$5:E$19,4) -> 0 | S5: =COUNTIF(F$5:F$19,4) -> 1 | T5: =COUNTIF(G$5:G$19,4) -> 0 | U5: =COUNTIF(H$5:H$19,4) -> 0 | V5: =COUNTIF(I$5:I$19,4) -> 0 | W5: =COUNTIF(J$5:J$19,4) -> 0 | X5: =COUNTIF(K$5:K$19,4) -> 0 | ... Z5: =COUNTIF(M$5:M$19,4) -> 0 | AA5: 0 | AB5: 0 | AC5: 2 | AD5: 4 | AG5: 1 | AH5: 13 Mar'25 | AI5: Initiatial Release | AJ5: Ishan
C6: Project Schedule Management | D6: 3 | E6: 2 | F6: 3 | G6: 2 | H6: 3 | I6: 0 | J6: 2 | K6: 2 | L6: 2 | M6: 2 | O6: LEVEL-3 | P6: Expert | Q6: =COUNTIF(D$5:D$19,3) -> 11 | R6: =COUNTIF(E$5:E$19,3) -> 0 | S6: =COUNTIF(F$5:F$19,3) -> 11 | T6: =COUNTIF(G$5:G$19,3) -> 3 | U6: =COUNTIF(H$5:H$19,3) -> 7 | V6: =COUNTIF(I$5:I$19,3) -> 0 | W6: =COUNTIF(J$5:J$19,3) -> 0 | X6: =COUNTIF(K$5:K$19,3) -> 8 | ... Z6: =COUNTIF(M$5:M$19,3) -> 1 | AA6: 21 | AB6: 44.4 | AC6: 48 | AD6: 47 | AG6: 2 | AH6: 25 Mar'25 | AI6: Bucketed Process & EPM skills | AJ6: Ishan & Martijn
C7: MLD process adherence | D7: 3 | E7: 2 | F7: 3 | G7: 3 | H7: 2 | I7: 0 | J7: 2 | K7: 3 | L7: 3 | M7: 2 | O7: LEVEL-2 | P7: Practitioner | Q7: =COUNTIF(D$5:D$19,2) -> 3 | R7: =COUNTIF(E$5:E$19,2) -> 13 | S7: =COUNTIF(F$5:F$19,2) -> 3 | T7: =COUNTIF(G$5:G$19,2) -> 12 | U7: =COUNTIF(H$5:H$19,2) -> 6 | V7: =COUNTIF(I$5:I$19,2) -> 0 | W7: =COUNTIF(J$5:J$19,2) -> 12 | X7: =COUNTIF(K$5:K$19,2) -> 5 | ... Z7: =COUNTIF(M$5:M$19,2) -> 12 | AA7: 46 | AB7: 59.2 | AC7: 74 | AD7: 67 | AG7: 3 | AH7: 27 May'25 | AI7: H1'25 targets updated | AJ7: Ishan
C8: Phase out process knowledge | D8: 3 | E8: 2 | F8: 3 | G8: 2 | H8: 2 | I8: 0 | J8: 2 | K8: NA | L8: 2 | M8: 1 | O8: LEVEL-1 | P8: Foundation | Q8: =COUNTIF(D$5:D$19,1) -> 0 | R8: =COUNTIF(E$5:E$19,1) -> 2 | S8: =COUNTIF(F$5:F$19,1) -> 0 | T8: =COUNTIF(G$5:G$19,1) -> 0 | U8: =COUNTIF(H$5:H$19,1) -> 2 | V8: =COUNTIF(I$5:I$19,1) -> 0 | W8: =COUNTIF(J$5:J$19,1) -> 3 | X8: =COUNTIF(K$5:K$19,1) -> 0 | ... Z8: =COUNTIF(M$5:M$19,1) -> 2 | AA8: 17 | AB8: 29.6 | AC8: 9 | AD8: 22 | AG8: 4 | AH8: 2 Jun'25 | AI8: Freddy included | AJ8: Ishan
C9: Portfolio & Supply Chain (Based on Supply Chain) | D9: 2 | E9: 2 | F9: 2 | G9: 2 | H9: 1 | I9: 0 | J9: 1 | K9: 3 | L9: 3 | M9: 2 | O9: LEVEL-0 | P9: Entry | Q9: =COUNTIF(D$5:D$19,0) -> 0 | R9: =COUNTIF(E$5:E$19,0) -> 0 | S9: =COUNTIF(F$5:F$19,0) -> 0 | T9: =COUNTIF(G$5:G$19,0) -> 0 | U9: =COUNTIF(H$5:H$19,0) -> 0 | V9: =COUNTIF(I$5:I$19,0) -> 15 | W9: =COUNTIF(J$5:J$19,0) -> 0 | X9: =COUNTIF(K$5:K$19,0) -> 0 | ... Z9: =COUNTIF(M$5:M$19,0) -> 0 | AA9: 2 | AB9: 14.8 | AC9: 15 | AD9: 8 | AG9: 5 | AH9: 45845 | AI9: Migrated to new template | AJ9: Sushruth
B10: EPM | C10: Risk Management | D10: 2 | E10: 1 | F10: 3 | G10: 2 | H10: 1 | I10: 0 | J10: 1 | K10: 2 | L10: 2 | M10: 1 | P10: NA | X10: 2
C11: Stakeholder Partnership (Based on Stakeholder Communication/Management) | D11: 3 | E11: 2 | F11: 3 | G11: 2 | H11: 2 | I11: 0 | J11: 2 | K11: 3 | L11: 3 | M11: 2 | Q11: Kirti | R11: Anjali | S11: Shiv | T11: Ashwini | U11: Rohit | V11: Mahesh | W11: Freddy | X11: Dayal | Y11: Sonam | Z11: Chetan | AA11: 2024 Baseline | AB11: H1'25 Target | AC11: H1'25 Actual | AD11: H2'25 Target | AE11: H2'25 Actual
C12: Ownership & Commitment (Based on Shows ownership) | D12: 3 | E12: 2 | F12: 3 | G12: 2 | H12: 3 | I12: 0 | J12: 2 | K12: 3 | L12: 3 | M12: 3
C13: Learning Agility | D13: 3 | E13: 2 | F13: 3 | G13: 2 | H13: 3 | I13: 0 | J13: 2 | K13: 2 | L13: 2 | M13: 2 | Y13: LEVEL-4 | Z13: Master | AA13: =AA5/$AA$4 -> 0 | AB13: =AB5/$AB$4 -> 0 | AC13: =AC5/$AC$4 -> 0.013513514 | AD13: =AD5/$AD$4 -> 0.027027027 | AE13: =AE5/$AE$4 -> #DIV/0!
C14: Judgement (Based on Problem Solving) | D14: 2 | E14: 2 | F14: 2 | G14: 2 | H14: 2 | I14: 0 | J14: 2 | K14: 2 | L14: 2 | M14: 2 | Y14: LEVEL-3 | Z14: Expert | AA14: =AA6/$AA$4 -> 0.24418605 | AB14: =AB6/$AB$4 -> 0.3 | AC14: =AC6/$AC$4 -> 0.32432432 | AD14: =AD6/$AD$4 -> 0.31756757 | AE14: =AE6/$AE$4 -> #DIV/0!
C15: Empowering leadership (Based on Conflict management) | D15: 3 | E15: 1 | F15: 3 | G15: 2 | H15: 2 | I15: 0 | J15: 1 | K15: 3 | L15: 2 | M15: 2 | Y15: LEVEL-2 | Z15: Practitioner | AA15: =AA7/$AA$4 -> 0.53488372 | AB15: =AB7/$AB$4 -> 0.4 | AC15: =AC7/$AC$4 -> 0.5 | AD15: =AD7/$AD$4 -> 0.4527027 | AE15: =AE7/$AE$4 -> #DIV/0!
C16: Business Acumen | D16: 3 | E16: 2 | F16: 2 | G16: 2 | H16: 3 | I16: 0 | J16: 2 | K16: 2 | L16: 2 | M16: 2 | Y16: LEVEL-1 | Z16: Foundation | AA16: =AA8/$AA$4 -> 0.19767442 | AB16: =AB8/$AB$4 -> 0.2 | AC16: =AC8/$AC$4 -> 0.060810811 | AD16: =AD8/$AD$4 -> 0.14864865 | AE16: =AE8/$AE$4 -> #DIV/0!
C17: Emotional Intelligence | D17: 3 | E17: 2 | F17: 3 | G17: 2 | H17: 3 | I17: 0 | J17: 2 | K17: 3 | L17: 3 | M17: 2 | Y17: LEVEL-0 | Z17: Entry | AA17: =AA9/$AA$4 -> 0.023255814 | AB17: =AB9/$AB$4 -> 0.1 | AC17: =AC9/$AC$4 -> 0.10135135 | AD17: =AD9/$AD$4 -> 0.054054054 | AE17: =AE9/$AE$4 -> #DIV/0!
C18: Network Performance | D18: 3 | E18: 2 | F18: 3 | G18: 2 | H18: 3 | I18: 0 | J18: 2 | K18: 3 | L18: 2 | M18: 2 | Y18: TOTAL | AA18: =SUM(AA13:AA17) -> 1 | AB18: =SUM(AB13:AB17) -> 1 | AC18: =SUM(AC13:AC17) -> 1 | AD18: =SUM(AD13:AD17) -> 1 | AE18: =SUM(AE13:AE17) -> #DIV/0!
C19: Customer Centricity | D19: 3 | E19: 2 | F19: 3 | G19: 3 | H19: 2 | I19: 0 | J19: 2 | K19: 3 | L19: 3 | M19: 2 | Y19: 2025 Goal | AA19: 0.65
D20: =AVERAGE(D5,D6,D7:D19) -> 2.8666667 | E20: =AVERAGE(E5,E6,E7:E19) -> 1.8666667 | F20: =AVERAGE(F5,F6,F7:F19) -> 2.8666667 | G20: =AVERAGE(G5,G6,G7:G19) -> 2.2 | H20: =AVERAGE(H5,H6,H7:H19) -> 2.3333333 | I20: =AVERAGE(I5,I6,I7:I19) -> 0 | J20: =AVERAGE(J5,J6,J7:J19) -> 1.8 | K20: =AVERAGE(K6:K7,K9:K19) -> 2.6153846 | L20: =AVERAGE(L5:L19) -> 2.4666667 | M20: =AVERAGE(M5:M19) -> 1.9333333 | Y20: YTD | AA20: =AC13+AC14+AC15 -> 0.83783784
Y21: H2'2025 Target | AA21: =SUM(AD13:AD15) -> 0.7972973
B22: First assessor | C22: Ishan/Dayal | Y22: Gap to Goal | AA22: =AA21-AA19 -> 0.1472973
B23: Second assessor | C23: Martijn Bosman/Johan Hendrix
B43: Freddy:
B44: Risk management guidance needed currently from Kelvin for right planning and execution, inline rated at Foundation level
B45: MLD process learning- currently doing fine, need to upgrade to next level.
B46: Can work on empowering leadership by leading the project team from front, currently not visible
B48: Anjali:
B49: Action plan and checklists were missing in latest review, need to catch-up on that to raise the level.
B50: Risk Mgmt: Mxd motor prod start before PSW release.
B51: Good Practise: LCM Menu card participation
B53: Shiv:
B54: Bigger scope projects good practise is to create a Gantt chart, can be cross learned by other TMs.
B55: He is new to Femdep, so supply chain understanding is getting better, will need sometime to reach next level.
B57: Mahesh:
... B63: Good Practise: LCM Menu card participation
C65: H1'25 Targets basis
B66: 1. EPM skills introduced (5 fresh evaluation criterias out of total 10 EPM skills)
B67: 2. Mahesh will be rated for the first time

Sheet PL
B2: STET-GB Competency Assessment 2026 | D2: Project Leaders
B3: Function group | C3: Process knowledge area/ EPM skill | D3: Kirti | E3: Anjali | F3: Pooja | G3: Shiv | H3: Rohit | I3: Mahesh D | J3: Freddy | K3: Ajinkya | L3: Pratik | M3: Mayur | N3: Mahesh U | O3: Chetan | S3: =D3 -> Kirti | T3: =E3 -> Anjali | U3: =F3 -> Pooja | V3: =G3 -> Shiv | W3: =H3 -> Rohit | X3: =I3 -> Mahesh D | Y3: =J3 -> Freddy | Z3: =K3 -> Ajinkya | ... AD3: =O3 -> Chetan | AE3: 2024 Baseline | AF3: 2025 Baseline | AG3: H1'26 Target | AH3: H1'26 Actual | AI3: H2'26 Target | AJ3: H2'26 Actual
B4: Process | C4: Market Introduction Plan/Phase-in | Q4: LEVEL-4 | R4: Master | S4: =COUNTIF(D$4:D$18,4) -> 0 | T4: =COUNTIF(E$4:E$18,4) -> 0 | U4: =COUNTIF(F$4:F$18,4) -> 0 | V4: =COUNTIF(G$4:G$18,4) -> 0 | W4: =COUNTIF(H$4:H$18,4) -> 0 | X4: =COUNTIF(I$4:I$18,4) -> 0 | Y4: =COUNTIF(J$4:J$18,4) -> 0 | Z4: =COUNTIF(K$4:K$18,4) -> 0 | ... AD4: =COUNTIF(O$4:O$18,4) -> 0 | AE4: 0 | AF4: 22 | AG4: 8 | AH4: =SUM(S4:AD4) -> 0 | AI4: 8 | AJ4: =SUM(S4:AD4) -> 0
C5: Project Schedule Management | Q5: LEVEL-3 | R5: Expert | S5: =COUNTIF(D$4:D$18,3) -> 0 | T5: =COUNTIF(E$4:E$18,3) -> 0 | U5: =COUNTIF(F$4:F$18,3) -> 0 | V5: =COUNTIF(G$4:G$18,3) -> 0 | W5: =COUNTIF(H$4:H$18,3) -> 0 | X5: =COUNTIF(I$4:I$18,3) -> 0 | Y5: =COUNTIF(J$4:J$18,3) -> 0 | Z5: =COUNTIF(K$4:K$18,3) -> 0 | ... AD5: =COUNTIF(O$4:O$18,3) -> 0 | AE5: 21 | AF5: 61 | AG5: 47 | AH5: =SUM(S5:AD5) -> 0 | AI5: 47 | AJ5: =SUM(S5:AD5) -> 0
C6: MLD process adherence | Q6: LEVEL-2 | R6: Practitioner | S6: =COUNTIF(D$4:D$18,2) -> 0 | T6: =COUNTIF(E$4:E$18,2) -> 0 | U6: =COUNTIF(F$4:F$18,2) -> 0 | V6: =COUNTIF(G$4:G$18,2) -> 0 | W6: =COUNTIF(H$4:H$18,2) -> 0 | X6: =COUNTIF(I$4:I$18,2) -> 0 | Y6: =COUNTIF(J$4:J$18,2) -> 0 | Z6: =COUNTIF(K$4:K$18,2) -> 0 | ... AD6: =COUNTIF(O$4:O$18,2) -> 0 | AE6: 46 | AF6: 41 | AG6: 72 | AH6: =SUM(S6:AD6) -> 0 | AI6: 72 | AJ6: =SUM(S6:AD6) -> 0
C7: Phase out process knowledge | Q7: LEVEL-1 | R7: Foundation | S7: =COUNTIF(D$4:D$18,1) -> 0 | T7: =COUNTIF(E$4:E$18,1) -> 0 | U7: =COUNTIF(F$4:F$18,1) -> 0 | V7: =COUNTIF(G$4:G$18,1) -> 0 | W7: =COUNTIF(H$4:H$18,1) -> 0 | X7: =COUNTIF(I$4:I$18,1) -> 0 | Y7: =COUNTIF(J$4:J$18,1) -> 0 | Z7: =COUNTIF(K$4:K$18,1) -> 0 | ... AD7: =COUNTIF(O$4:O$18,1) -> 0 | AE7: 17 | AF7: 9 | AG7: 53 | AH7: =SUM(S7:AD7) -> 0 | AI7: 53 | AJ7: =SUM(S7:AD7) -> 0
C8: Portfolio & Supply Chain (Based on Supply Chain) | Q8: LEVEL-0 | R8: Entry | S8: =COUNTIF(D$4:D$18,0) -> 0 | T8: =COUNTIF(E$4:E$18,0) -> 0 | U8: =COUNTIF(F$4:F$18,0) -> 0 | V8: =COUNTIF(G$4:G$18,0) -> 0 | W8: =COUNTIF(H$4:H$18,0) -> 0 | X8: =COUNTIF(I$4:I$18,0) -> 0 | Y8: =COUNTIF(J$4:J$18,0) -> 0 | Z8: =COUNTIF(K$4:K$18,0) -> 0 | ... AD8: =COUNTIF(O$4:O$18,0) -> 0 | AE8: 2 | AF8: 0 | AG8: 0 | AH8: =SUM(S8:AD8) -> 0 | AI8: 0 | AJ8: =SUM(S8:AD8) -> 0
B9: EPM | C9: Risk Management | S9: =SUM(S4:S8) -> 0 | T9: =SUM(T4:T8) -> 0 | U9: =SUM(U4:U8) -> 0 | V9: =SUM(V4:V8) -> 0 | W9: =SUM(W4:W8) -> 0 | X9: =SUM(X4:X8) -> 0 | Y9: =SUM(Y4:Y8) -> 0 | Z9: =SUM(Z4:Z8) -> 0 | ... AG9: =SUM(AG4:AG8) -> 180 | AH9: 180 | AI9: =SUM(AI4:AI8) -> 180 | AJ9: 180
C10: Stakeholder Partnership (Based on Stakeholder Communication/Management)
C11: Ownership & Commitment (Based on Shows ownership) | AB11: LEVEL 2+ | AC11: Practitioner+ | AE11: =SUM(AE12:AE14) -> 0.77906977 | AF11: =SUM(AF12:AF14) -> 0.93233083 | AG11: =SUM(AG12:AG14) -> 0.70555556 | AH11: =SUM(AH12:AH14) -> 0 | AI11: =SUM(AI12:AI14) -> 0.70555556 | AJ11: =SUM(AJ12:AJ14) -> 0
C12: Learning Agility | AB12: LEVEL-4 | AC12: Master | AE12: =AE4/$AE$9 -> 0 | AF12: =AF4/$AF$9 -> 0.16541353 | AG12: =AG4/$AG$9 -> 0.044444444 | AH12: =AH4/$AH$9 -> 0 | AI12: =AI4/$AI$9 -> 0.044444444 | AJ12: =AJ4/$AJ$9 -> 0
C13: Judgement (Based on Problem Solving) | AB13: LEVEL-3 | AC13: Expert | AE13: =AE5/$AE$9 -> 0.24418605 | AF13: =AF5/$AF$9 -> 0.45864662 | AG13: =AG5/$AG$9 -> 0.26111111 | AH13: =AH5/$AH$9 -> 0 | AI13: =AI5/$AI$9 -> 0.26111111 | AJ13: =AJ5/$AJ$9 -> 0
C14: Empowering leadership (Based on Conflict management) | AB14: LEVEL-2 | AC14: Practitioner | AE14: =AE6/$AE$9 -> 0.53488372 | AF14: =AF6/$AF$9 -> 0.30827068 | AG14: =AG6/$AG$9 -> 0.4 | AH14: =AH6/$AH$9 -> 0 | AI14: =AI6/$AI$9 -> 0.4 | AJ14: =AJ6/$AJ$9 -> 0
C15: Business Acumen | AB15: LEVEL-1 | AC15: Foundation | AE15: =AE7/$AE$9 -> 0.19767442 | AF15: =AF7/$AF$9 -> 0.067669173 | AG15: =AG7/$AG$9 -> 0.29444444 | AH15: =AH7/$AH$9 -> 0 | AI15: =AI7/$AI$9 -> 0.29444444 | AJ15: =AJ7/$AJ$9 -> 0
C16: Emotional Intelligence | AB16: LEVEL-0 | AC16: Entry | AE16: =AE8/$AE$9 -> 0.023255814 | AF16: =AF8/$AF$9 -> 0 | AG16: =AG8/$AG$9 -> 0 | AH16: =AH8/$AH$9 -> 0 | AI16: =AI8/$AI$9 -> 0 | AJ16: =AJ8/$AJ$9 -> 0
C17: Network Performance | AB17: TOTAL | AE17: =AE9/$AE$9 -> 1 | AF17: =AF9/$AF$9 -> 1 | AG17: =AG9/$AG$9 -> 1 | AH17: =AH9/$AH$9 -> 1 | AI17: =AI9/$AI$9 -> 1 | AJ17: =AJ9/$AJ$9 -> 1
C18: Customer Centricity | AB18: 2026 Goal | AE18: 0.7
D19: =AVERAGE(D4:D18) -> #DIV/0! | E19: =AVERAGE(E4:E18) -> #DIV/0! | F19: =AVERAGE(F4:F18) -> #DIV/0! | G19: =AVERAGE(G4:G18) -> #DIV/0! | H19: =AVERAGE(H4:H18) -> #DIV/0! | I19: =AVERAGE(I4:I18) -> #DIV/0! | J19: =AVERAGE(J4:J18) -> #DIV/0! | K19: =AVERAGE(K4:K18) -> #DIV/0! | ... O19: =AVERAGE(O4:O18) -> #DIV/0! | AB19: YTD
AB20: H1'2026 Target | AE20: =SUM(AG12:AG14) -> 0.70555556
B21: First assessor | C21: Ishan & LCM-PMs | AB21: Gap to 2026 Goal | AE21: =AE20-AE18 -> 0.0055555556
B22: Second assessor | C22: Martijn Bosman

Sheet ME-H1
B2: STET-GB Competency Assessment 2025 | D2: Mechanical Engineering
D3: Jena | E3: Nishita | F3: Nutan | G3: Sagar | H3: Mukesh | I3: Kishore | J3: Riddin | N3: =SUM(N4:N8) -> 11 | O3: =SUM(O4:O8) -> 11 | P3: =SUM(P4:P8) -> 11 | Q3: =SUM(Q4:Q8) -> 11 | R3: =SUM(R4:R8) -> 11 | S3: =SUM(S4:S8) -> 11 | T3: =SUM(T4:T8) -> 11 | U3: =SUM(U4:U8) -> 34 | V3: =SUM(V4:V9) -> 77 | W3: =SUM(W4:W9) -> 77 | X3: =SUM(X4:X9) -> 77 | Y3: =SUM(Y4:Y9) -> 0
C4: CAD Software (NX, CREO) | D4: 4 | E4: 3 | F4: 2 | G4: 2 | H4: 1 | I4: 2 | J4: 1 | L4: LEVEL-4 | M4: Master | N4: =COUNTIF(D$4:D$14,4) -> 5 | O4: =COUNTIF(E$4:E$14,4) -> 0 | P4: =COUNTIF(F$4:F$14,4) -> 0 | Q4: =COUNTIF(G$4:G$14,4) -> 0 | R4: =COUNTIF(H$4:H$14,4) -> 0 | S4: =COUNTIF(I$4:I$14,4) -> 0 | T4: =COUNTIF(J$4:J$14,4) -> 1 | U4: 0 | V4: 0 | W4: 6 | X4: 6
C5: Design for Tolerances / GD&T | D5: 4 | E5: 2 | F5: 1 | G5: 2 | H5: 1 | I5: 2 | J5: 1 | L5: LEVEL-3 | M5: Expert | N5: =COUNTIF(D$4:D$14,3) -> 0 | O5: =COUNTIF(E$4:E$14,3) -> 6 | P5: =COUNTIF(F$4:F$14,3) -> 1 | Q5: =COUNTIF(G$4:G$14,3) -> 2 | R5: =COUNTIF(H$4:H$14,3) -> 1 | S5: =COUNTIF(I$4:I$14,3) -> 1 | T5: =COUNTIF(J$4:J$14,3) -> 0 | U5: 0 | V5: 5 | W5: 11 | X5: 11
C6: Simulations, e.g. FEA | D6: 1 | E6: 1 | F6: 1 | G6: 3 | H6: 1 | I6: 1 | J6: 1 | L6: LEVEL-2 | M6: Practitioner | N6: =COUNTIF(D$4:D$14,2) -> 4 | O6: =COUNTIF(E$4:E$14,2) -> 3 | P6: =COUNTIF(F$4:F$14,2) -> 7 | Q6: =COUNTIF(G$4:G$14,2) -> 7 | R6: =COUNTIF(H$4:H$14,2) -> 2 | S6: =COUNTIF(I$4:I$14,2) -> 8 | T6: =COUNTIF(J$4:J$14,2) -> 4 | U6: 13 | V6: 31 | W6: 35 | X6: 40
C7: Plastic parts design, DFM, DFA | D7: 4 | E7: 3 | F7: 2 | G7: 2 | H7: 1 | I7: 2 | J7: 1 | L7: LEVEL-1 | M7: Foundation | N7: =COUNTIF(D$4:D$14,1) -> 2 | O7: =COUNTIF(E$4:E$14,1) -> 2 | P7: =COUNTIF(F$4:F$14,1) -> 3 | Q7: =COUNTIF(G$4:G$14,1) -> 2 | R7: =COUNTIF(H$4:H$14,1) -> 8 | S7: =COUNTIF(I$4:I$14,1) -> 1 | T7: =COUNTIF(J$4:J$14,1) -> 6 | U7: 10 | V7: 36 | W7: 24 | X7: 20
C8: Windchill Design Engineer | D8: 4 | E8: 3 | F8: 3 | G8: 3 | H8: 3 | I8: 3 | J8: 4 | L8: LEVEL-0 | M8: Entry | N8: =COUNTIF(D$4:D$14,0) -> 0 | O8: =COUNTIF(E$4:E$14,0) -> 0 | P8: =COUNTIF(F$4:F$14,0) -> 0 | Q8: =COUNTIF(G$4:G$14,0) -> 0 | R8: =COUNTIF(H$4:H$14,0) -> 0 | S8: =COUNTIF(I$4:I$14,0) -> 1 | T8: =COUNTIF(J$4:J$14,0) -> 0 | U8: 11 | V8: 5 | W8: 1 | X8: 0
C9: Doors – requirements mgmt | D9: 1 | E9: 1 | F9: 1 | G9: 1 | H9: 1 | I9: 0 | J9: 1 | M9: NA
C10: ME CAD WoW | D10: 4 | E10: 3 | F10: 2 | G10: 2 | H10: 1 | I10: 2 | J10: 1 | N10: =D3 -> Jena | O10: =E3 -> Nishita | P10: =F3 -> Nutan | Q10: =G3 -> Sagar | R10: =H3 -> Mukesh | S10: =I3 -> Kishore | T10: =J3 -> Riddin | U10: 2024 Baseline | V10: H1'25 Target | W10: H1'25 Actual | X10: H2'25 Target | Y10: H2'25 Actual
C11: Stakeholder Communication (Soft Skill ) | D11: 2 | E11: 3 | F11: 2 | G11: 2 | H11: 2 | I11: 2 | J11: 2
C12: Articulation and ability to communicate(Presentation Skills ) | D12: 2 | E12: 2 | F12: 2 | G12: 1 | H12: 1 | I12: 2 | J12: 2 | S12: LEVEL-4 | T12: Master | U12: =U4/$U$3 -> 0 | V12: =V4/$V$3 -> 0 | W12: =W4/$W$3 -> 0.077922078 | X12: =X4/$X$3 -> 0.077922078 | Y12: =Y4/$Y$3 -> #DIV/0!
C13: Ownership and Accountability (Say Do Ratio) | D13: 2 | E13: 2 | F13: 2 | G13: 2 | H13: 1 | I13: 2 | J13: 2 | S13: LEVEL-3 | T13: Expert | U13: =U5/$U$3 -> 0 | V13: =V5/$V$3 -> 0.064935065 | W13: =W5/$W$3 -> 0.14285714 | X13: =X5/$X$3 -> 0.14285714 | Y13: =Y5/$Y$3 -> #DIV/0!
C14: Assertiveness (Soft Skills) | D14: 2 | E14: 3 | F14: 2 | G14: 2 | H14: 2 | I14: 2 | J14: 2 | S14: LEVEL-2 | T14: Practitioner | U14: =U6/$U$3 -> 0.38235294 | V14: =V6/$V$3 -> 0.4025974 | W14: =W6/$W$3 -> 0.45454545 | X14: =X6/$X$3 -> 0.51948052 | Y14: =Y6/$Y$3 -> #DIV/0!
D15: =AVERAGE(D4:D14) -> 2.7272727 | E15: =AVERAGE(E4:E14) -> 2.3636364 | F15: =AVERAGE(F4:F14) -> 1.8181818 | G15: =AVERAGE(G4:G14) -> 2 | H15: =AVERAGE(H4:H14) -> 1.3636364 | I15: =AVERAGE(I4:I14) -> 1.8181818 | J15: =AVERAGE(J4:J14) -> 1.6363636 | S15: LEVEL-1 | T15: Foundation | U15: =U7/$U$3 -> 0.29411765 | V15: =V7/$V$3 -> 0.46753247 | W15: =W7/$W$3 -> 0.31168831 | X15: =X7/$X$3 -> 0.25974026 | Y15: =Y7/$Y$3 -> #DIV/0!
S16: LEVEL-0 | T16: Entry | U16: =U8/$U$3 -> 0.32352941 | V16: =V8/$V$3 -> 0.064935065 | W16: =W8/$W$3 -> 0.012987013 | X16: =X8/$X$3 -> 0 | Y16: =Y8/$Y$3 -> #DIV/0!
B17: First assessor | C17: Adarsh Shrivastava | S17: TOTAL | U17: =SUM(U12:U16) -> 1 | V17: =SUM(V12:V16) -> 1 | W17: =SUM(W12:W16) -> 1 | X17: =SUM(X12:X16) -> 1 | Y17: =SUM(Y12:Y16) -> #DIV/0!
B18: Second assessor | C18: Oege Smedinga | S18: 2025 Goal | U18: 0.65
S19: YTD | U19: =W12+W13+W14 -> 0.67532468
S20: H2'2025 Target | U20: =SUM(X12:X14) -> 0.74025974
S21: Gap to Goal | U21: =U19-U18 -> 0.025324675

Sheet PE-H1
B2: STET-GB Competency Assessment 2025 | D2: Packaging Engineering
D3: Pooja | E3: Laxman | F3: Haseeb | G3: Amit | H3: Sourabh | I3: Shubham | J3: Vedanand | N3: =SUM(N4:N8) -> 11 | O3: =SUM(O4:O8) -> 12 | P3: =SUM(P4:P8) -> 10 | Q3: =SUM(Q4:Q8) -> 10 | R3: =SUM(R4:R8) -> 12 | S3: =SUM(S4:S8) -> 12 | T3: =SUM(T4:T8) -> 12 | U3: =SUM(U4:U8) -> 67 | ... Y3: =SUM(Y4:Y8) -> 0
C4: MLD lead for Packaging (process adherence) | D4: 3 | E4: 3 | F4: 3 | G4: 0 | H4: 1 | I4: 2 | J4: 2 | L4: LEVEL-4 | M4: Master | N4: =COUNTIF(D$4:D$15,4) -> 0 | O4: =COUNTIF(E$4:E$15,4) -> 0 | P4: =COUNTIF(F$4:F$15,4) -> 0 | Q4: =COUNTIF(G$4:G$15,4) -> 0 | R4: =COUNTIF(H$4:H$15,4) -> 0 | S4: =COUNTIF(I$4:I$15,4) -> 0 | T4: =COUNTIF(J$4:J$15,4) -> 0 | U4: 0 | V4: 0 | W4: 0 | X4: 0
C5: Prototyping & workshop (Plotter & Equipment's) | D5: 2 | E5: 3 | F5: 3 | G5: 1 | H5: 3 | I5: 3 | J5: 1 | L5: LEVEL-3 | M5: Expert | N5: =COUNTIF(D$4:D$15,3) -> 8 | O5: =COUNTIF(E$4:E$15,3) -> 5 | P5: =COUNTIF(F$4:F$15,3) -> 3 | Q5: =COUNTIF(G$4:G$15,3) -> 0 | R5: =COUNTIF(H$4:H$15,3) -> 2 | S5: =COUNTIF(I$4:I$15,3) -> 7 | T5: =COUNTIF(J$4:J$15,3) -> 1 | U5: 17 | V5: 26 | W5: 26 | X5: 29
C6: CAD development (Nx) - Limited responsibility | D6: 1 | E6: 1 | F6: NA | G6: 0 | H6: 1 | I6: 3 | J6: 1 | L6: LEVEL-2 | M6: Practitioner | N6: =COUNTIF(D$4:D$15,2) -> 1 | O6: =COUNTIF(E$4:E$15,2) -> 5 | P6: =COUNTIF(F$4:F$15,2) -> 5 | Q6: =COUNTIF(G$4:G$15,2) -> 0 | R6: =COUNTIF(H$4:H$15,2) -> 4 | S6: =COUNTIF(I$4:I$15,2) -> 3 | T6: =COUNTIF(J$4:J$15,2) -> 6 | U6: 23 | V6: 24 | W6: 24 | X6: 32
C7: Change management WC (CR) | D7: 3 | E7: 3 | F7: 3 | G7: 1 | H7: 2 | I7: 3 | J7: 2 | L7: LEVEL-1 | M7: Foundation | N7: =COUNTIF(D$4:D$15,1) -> 2 | O7: =COUNTIF(E$4:E$15,1) -> 2 | P7: =COUNTIF(F$4:F$15,1) -> 2 | Q7: =COUNTIF(G$4:G$15,1) -> 3 | R7: =COUNTIF(H$4:H$15,1) -> 6 | S7: =COUNTIF(I$4:I$15,1) -> 2 | T7: =COUNTIF(J$4:J$15,1) -> 5 | U7: 22 | V7: 22 | W7: 22 | X7: 11
C8: Packmaster (PDLM) | D8: NA | E8: 2 | F8: NA | G8: 0 | H8: 2 | I8: 3 | J8: 1 | L8: LEVEL-0 | M8: Entry | N8: =COUNTIF(D$4:D$15,0) -> 0 | O8: =COUNTIF(E$4:E$15,0) -> 0 | P8: =COUNTIF(F$4:F$15,0) -> 0 | Q8: =COUNTIF(G$4:G$15,0) -> 7 | R8: =COUNTIF(H$4:H$15,0) -> 0 | S8: =COUNTIF(I$4:I$15,0) -> 0 | T8: =COUNTIF(J$4:J$15,0) -> 0 | U8: 5 | V8: 7 | W8: 7 | X8: 7
C9: Logistics Data | D9: 3 | E9: 3 | F9: 2 | G9: 1 | H9: 3 | I9: 3 | J9: 1 | M9: NA | N9: 1 | O9: 0 | P9: 2 | Q9: 2 | R9: 0 | S9: 0 | T9: 1 | U9: 5 | V9: 5 | W9: 5 | X9: 5
C10: Testing & Verification | D10: 3 | E10: 1 | F10: 2 | G10: NA | H10: 1 | I10: 3 | J10: 1 | N10: Pooja | O10: Laxman | P10: Haseeb | Q10: Amit | R10: Sourabh | S10: Shubham | T10: Vedanand | U10: 2024 Baseline | V10: H1'25 Target | W10: H1'25 Actual | X10: H2'25 Target | Y10: H2'25 Actual
C11: Introduction to Project Management | D11: 3 | E11: 3 | F11: 2 | G11: NA | H11: 1 | I11: 3 | J11: 2
C12: Stakeholder Communication (Soft Skill ) | D12: 3 | E12: 2 | F12: 2 | G12: 0 | H12: 1 | I12: 2 | J12: 2 | S12: LEVEL-4 | T12: Master | U12: =U4/$U$3 -> 0 | V12: =V4/$V$3 -> 0 | W12: =W4/$W$3 -> 0 | X12: =X4/$X$3 -> 0
C13: Articulation and ability to communicate(Presentation Skills ) | D13: 1 | E13: 2 | F13: 1 | G13: 0 | H13: 1 | I13: 1 | J13: 2 | S13: LEVEL-3 | T13: Expert | U13: =U5/$U$3 -> 0.25373134 | V13: =V5/$V$3 -> 0.32911392 | W13: =W5/$W$3 -> 0.32911392 | X13: =X5/$X$3 -> 0.36708861
C14: Ownership and Accountability (Say Do Ratio) | D14: 3 | E14: 2 | F14: 2 | G14: 0 | H14: 2 | I14: 2 | J14: 2 | S14: LEVEL-2 | T14: Practitioner | U14: =U6/$U$3 -> 0.34328358 | V14: =V6/$V$3 -> 0.30379747 | W14: =W6/$W$3 -> 0.30379747 | X14: =X6/$X$3 -> 0.40506329
C15: Assertiveness (Soft Skills) | D15: 3 | E15: 2 | F15: 1 | G15: 0 | H15: 2 | I15: 1 | J15: 3 | S15: LEVEL-1 | T15: Foundation | U15: =U7/$U$3 -> 0.32835821 | V15: =V7/$V$3 -> 0.27848101 | W15: =W7/$W$3 -> 0.27848101 | X15: =X7/$X$3 -> 0.13924051
D16: =AVERAGE(D4:D15) -> 2.5454545 | E16: =AVERAGE(E4:E15) -> 2.25 | F16: =AVERAGE(F4:F15) -> 2.1 | G16: =AVERAGE(G4:G15) -> 0.3 | H16: =AVERAGE(H4:H15) -> 1.6666667 | I16: =AVERAGE(I4:I15) -> 2.4166667 | J16: =AVERAGE(J4:J15) -> 1.6666667 | S16: LEVEL-0 | T16: Entry | U16: =U8/$U$3 -> 0.074626866 | V16: =V8/$V$3 -> 0.088607595 | W16: =W8/$W$3 -> 0.088607595 | X16: =X8/$X$3 -> 0.088607595
S17: TOTAL | U17: =SUM(U12:U16) -> 1 | V17: =SUM(V12:V16) -> 1 | W17: =SUM(W12:W16) -> 1 | X17: =SUM(X12:X16) -> 1
B18: First assessor | C18: Kamal | S18: 2025 Goal | U18: 0.65
B19: Second assessor | C19: Sjoukje | S19: YTD | U19: =W12+W13+W14 -> 0.63291139
S20: H2'2025 Target | U20: =SUM(X12:X14) -> 0.7721519
S21: Gap to Goal | U21: =U19-U18 -> -0.017088608

Sheet ME
B2: STET-GB Competency Assessment 2026 | D2: Mechanical Engineers
D3: Jena | E3: Nishita | F3: Nutan | G3: Sagar | H3: Mukesh | I3: Kishore | J3: Gitimaya | K3: Krishna | L3: 577554 | M3: 566004 | Q3: =D3 -> Jena | R3: =E3 -> Nishita | S3: =F3 -> Nutan | T3: =G3 -> Sagar | U3: =H3 -> Mukesh | V3: =I3 -> Kishore | W3: =J3 -> Gitimaya | X3: =K3 -> Krishna | ... Z3: =M3 -> 566004 | AC3: 2024 Baseline | AD3: 2025 Baseline | AE3: H1'26 Target | AF3: H1'26 Actual | AG3: H2'26 Target | AH3: H2'26 Actual
C4: CAD Software (NX, CREO) | O4: LEVEL-4 | P4: Master | Q4: =COUNTIF(D$4:D$14,4) -> 0 | R4: =COUNTIF(E$4:E$14,4) -> 0 | S4: =COUNTIF(F$4:F$14,4) -> 0 | T4: =COUNTIF(G$4:G$14,4) -> 0 | U4: =COUNTIF(H$4:H$14,4) -> 0 | V4: =COUNTIF(I$4:I$14,4) -> 0 | W4: =COUNTIF(J$4:J$14,4) -> 0 | X4: =COUNTIF(K$4:K$14,4) -> 0 | ... Z4: =COUNTIF(M$4:M$14,4) -> 0 | AC4: 0 | AD4: 14 | AE4: =SUM(Q4:Z4) -> 0 | AG4: 14
C5: Design for Tolerances / GD&T | O5: LEVEL-3 | P5: Expert | Q5: =COUNTIF(D$4:D$14,3) -> 0 | R5: =COUNTIF(E$4:E$14,3) -> 0 | S5: =COUNTIF(F$4:F$14,3) -> 0 | T5: =COUNTIF(G$4:G$14,3) -> 0 | U5: =COUNTIF(H$4:H$14,3) -> 0 | V5: =COUNTIF(I$4:I$14,3) -> 0 | W5: =COUNTIF(J$4:J$14,3) -> 0 | X5: =COUNTIF(K$4:K$14,3) -> 0 | ... Z5: =COUNTIF(M$4:M$14,3) -> 0 | AC5: 0 | AD5: 18 | AE5: =SUM(Q5:Z5) -> 0 | AG5: 18
C6: Simulations, e.g. FEA | O6: LEVEL-2 | P6: Practitioner | Q6: =COUNTIF(D$4:D$14,2) -> 0 | R6: =COUNTIF(E$4:E$14,2) -> 0 | S6: =COUNTIF(F$4:F$14,2) -> 0 | T6: =COUNTIF(G$4:G$14,2) -> 0 | U6: =COUNTIF(H$4:H$14,2) -> 0 | V6: =COUNTIF(I$4:I$14,2) -> 0 | W6: =COUNTIF(J$4:J$14,2) -> 0 | X6: =COUNTIF(K$4:K$14,2) -> 0 | ... Z6: =COUNTIF(M$4:M$14,2) -> 0 | AC6: 13 | AD6: 21 | AE6: =SUM(Q6:Z6) -> 0 | AG6: 21
C7: Plastic parts design, DFM, DFA | O7: LEVEL-1 | P7: Foundation | Q7: =COUNTIF(D$4:D$14,1) -> 0 | R7: =COUNTIF(E$4:E$14,1) -> 0 | S7: =COUNTIF(F$4:F$14,1) -> 0 | T7: =COUNTIF(G$4:G$14,1) -> 0 | U7: =COUNTIF(H$4:H$14,1) -> 0 | V7: =COUNTIF(I$4:I$14,1) -> 0 | W7: =COUNTIF(J$4:J$14,1) -> 0 | X7: =COUNTIF(K$4:K$14,1) -> 0 | ... Z7: =COUNTIF(M$4:M$14,1) -> 0 | AC7: 10 | AD7: 12 | AE7: =SUM(Q7:Z7) -> 0 | AG7: 56
C8: Windchill Design Engineer | O8: LEVEL-0 | P8: Entry | Q8: =COUNTIF(D$4:D$14,0) -> 0 | R8: =COUNTIF(E$4:E$14,0) -> 0 | S8: =COUNTIF(F$4:F$14,0) -> 0 | T8: =COUNTIF(G$4:G$14,0) -> 0 | U8: =COUNTIF(H$4:H$14,0) -> 0 | V8: =COUNTIF(I$4:I$14,0) -> 0 | W8: =COUNTIF(J$4:J$14,0) -> 0 | X8: =COUNTIF(K$4:K$14,0) -> 0 | ... Z8: =COUNTIF(M$4:M$14,0) -> 0 | AC8: 11 | AD8: 1 | AE8: =SUM(Q8:Z8) -> 0 | AG8: 1
C9: Doors – requirements mgmt | Q9: =SUM(Q4:Q8) -> 0 | R9: =SUM(R4:R8) -> 0 | S9: =SUM(S4:S8) -> 0 | T9: =SUM(T4:T8) -> 0 | U9: =SUM(U4:U8) -> 0 | V9: =SUM(V4:V8) -> 0 | W9: =SUM(W4:W8) -> 0 | X9: =SUM(X4:X8) -> 0 | ... Z9: =SUM(Z4:Z8) -> 0 | AC9: =SUM(AC4:AC8) -> 34 | AD9: =SUM(AD4:AD8) -> 66 | AE9: =SUM(AE4:AE8) -> 0 | AF9: 110 | AG9: =SUM(AG4:AG8) -> 110 | AH9: 110
C10: ME CAD WoW
C11: Stakeholder Communication (Soft Skill ) | Z11: LEVEL 2+ | AA11: Practitioner+ | AC11: =SUM(AC12:AC14) -> 0.38235294 | AD11: =SUM(AD12:AD14) -> 0.8030303 | AE11: =SUM(AE12:AE14) -> #DIV/0! | AF11: =SUM(AF12:AF14) -> 0 | AG11: =SUM(AG12:AG14) -> 0.48181818 | AH11: =SUM(AH12:AH14) -> 0
C12: Articulation and ability to communicate(Presentation Skills ) | Z12: LEVEL-4 | AA12: Master | AC12: =AC4/$AC$9 -> 0 | AD12: =AD4/$AD$9 -> 0.21212121 | AE12: =AE4/$AE$9 -> #DIV/0! | AF12: =AF4/$AF$9 -> 0 | AG12: =AG4/$AG$9 -> 0.12727273 | AH12: =AH4/$AH$9 -> 0
C13: Ownership and Accountability (Say Do Ratio) | Z13: LEVEL-3 | AA13: Expert | AC13: =AC5/$AC$9 -> 0 | AD13: =AD5/$AD$9 -> 0.27272727 | AE13: =AE5/$AE$9 -> #DIV/0! | AF13: =AF5/$AF$9 -> 0 | AG13: =AG5/$AG$9 -> 0.16363636 | AH13: =AH5/$AH$9 -> 0
C14: Assertiveness (Soft Skills) | Z14: LEVEL-2 | AA14: Practitioner | AC14: =AC6/$AC$9 -> 0.38235294 | AD14: =AD6/$AD$9 -> 0.31818182 | AE14: =AE6/$AE$9 -> #DIV/0! | AF14: =AF6/$AF$9 -> 0 | AG14: =AG6/$AG$9 -> 0.19090909 | AH14: =AH6/$AH$9 -> 0
D15: =AVERAGE(D4:D14) -> #DIV/0! | E15: =AVERAGE(E4:E14) -> #DIV/0! | F15: =AVERAGE(F4:F14) -> #DIV/0! | G15: =AVERAGE(G4:G14) -> #DIV/0! | H15: =AVERAGE(H4:H14) -> #DIV/0! | I15: =AVERAGE(I4:I14) -> #DIV/0! | J15: =AVERAGE(J4:J14) -> #DIV/0! | K15: =AVERAGE(K4:K14) -> #DIV/0! | ... M15: =AVERAGE(M4:M14) -> #DIV/0! | Z15: LEVEL-1 | AA15: Foundation | AC15: =AC7/$AC$9 -> 0.29411765 | AD15: =AD7/$AD$9 -> 0.18181818 | AE15: =AE7/$AE$9 -> #DIV/0! | AF15: =AF7/$AF$9 -> 0 | AG15: =AG7/$AG$9 -> 0.50909091 | AH15: =AH7/$AH$9 -> 0
Z16: LEVEL-0 | AA16: Entry | AC16: =AC8/$AC$9 -> 0.32352941 | AD16: =AD8/$AD$9 -> 0.015151515 | AE16: =AE8/$AE$9 -> #DIV/0! | AF16: =AF8/$AF$9 -> 0 | AG16: =AG8/$AG$9 -> 0.0090909091 | AH16: =AH8/$AH$9 -> 0
B17: First assessor | C17: Adarsh Shrivastava | Z17: TOTAL | AC17: =AC9/$AC$9 -> 1 | AD17: =AD9/$AD$9 -> 1 | AE17: =AE9/$AE$9 -> #DIV/0! | AF17: =AF9/$AF$9 -> 1 | AG17: =AG9/$AG$9 -> 1 | AH17: =AH9/$AH$9 -> 1
B18: Second assessor | C18: Oege Smedinga | Z18: 2026 Goal | AC18: 0.7
Z19: YTD
Z20: H1'2026 Target | AC20: =SUM(AE12:AE14) -> #DIV/0!
Z21: Gap to 2026 Goal | AC21: =AC18-AC20 -> #DIV/0!

Sheet PE
B2: STET-GB Competency Assessment 2026 | D2: Packaging Engineers
D3: Pooja | E3: Laxman | F3: Haseeb | G3: Vaibhav | H3: Sourabh | I3: Shubham | J3: Vedanand | R3: =D3 -> Pooja | S3: =E3 -> Laxman | T3: =F3 -> Haseeb | U3: =G3 -> Vaibhav | V3: =H3 -> Sourabh | W3: =I3 -> Shubham | X3: =J3 -> Vedanand | AD3: 2024 Baseline | AE3: 2025 Baseline | AF3: H1'26 Target | AG3: H1'26 Actual | AH3: H2'26 Target | AI3: H2'26 Actual
C4: MLD lead for Packaging (process adherence) | P4: LEVEL-4 | Q4: Master | R4: =COUNTIF(D$4:D$15,4) -> 0 | S4: =COUNTIF(E$4:E$15,4) -> 0 | T4: =COUNTIF(F$4:F$15,4) -> 0 | U4: =COUNTIF(G$4:G$15,4) -> 0 | V4: =COUNTIF(H$4:H$15,4) -> 0 | W4: =COUNTIF(I$4:I$15,4) -> 0 | X4: =COUNTIF(J$4:J$15,4) -> 0 | AD4: 0 | AE4: 2 | AF4: =SUM(R4:X4) -> 0 | AH4: 2
C5: Prototyping & workshop (Plotter & Equipment's) | P5: LEVEL-3 | Q5: Expert | R5: =COUNTIF(D$4:D$15,3) -> 0 | S5: =COUNTIF(E$4:E$15,3) -> 0 | T5: =COUNTIF(F$4:F$15,3) -> 0 | U5: =COUNTIF(G$4:G$15,3) -> 0 | V5: =COUNTIF(H$4:H$15,3) -> 0 | W5: =COUNTIF(I$4:I$15,3) -> 0 | X5: =COUNTIF(J$4:J$15,3) -> 0 | AD5: 17 | AE5: 26 | AF5: =SUM(R5:X5) -> 0 | AH5: 26
C6: CAD development (Nx) - Limited responsibility | P6: LEVEL-2 | Q6: Practitioner | R6: =COUNTIF(D$4:D$15,2) -> 0 | S6: =COUNTIF(E$4:E$15,2) -> 0 | T6: =COUNTIF(F$4:F$15,2) -> 0 | U6: =COUNTIF(G$4:G$15,2) -> 0 | V6: =COUNTIF(H$4:H$15,2) -> 0 | W6: =COUNTIF(I$4:I$15,2) -> 0 | X6: =COUNTIF(J$4:J$15,2) -> 0 | AD6: 23 | AE6: 31 | AF6: =SUM(R6:X6) -> 0 | AH6: 30
C7: Change management WC (CR) | P7: LEVEL-1 | Q7: Foundation | R7: =COUNTIF(D$4:D$15,1) -> 0 | S7: =COUNTIF(E$4:E$15,1) -> 0 | T7: =COUNTIF(F$4:F$15,1) -> 0 | U7: =COUNTIF(G$4:G$15,1) -> 0 | V7: =COUNTIF(H$4:H$15,1) -> 0 | W7: =COUNTIF(I$4:I$15,1) -> 0 | X7: =COUNTIF(J$4:J$15,1) -> 0 | AD7: 22 | AE7: 10 | AF7: =SUM(R7:X7) -> 0 | AH7: 23
C8: Packmaster (PDLM & LCM MLU) | P8: LEVEL-0 | Q8: Entry | R8: =COUNTIF(D$4:D$15,0) -> 0 | S8: =COUNTIF(E$4:E$15,0) -> 0 | T8: =COUNTIF(F$4:F$15,0) -> 0 | U8: =COUNTIF(G$4:G$15,0) -> 0 | V8: =COUNTIF(H$4:H$15,0) -> 0 | W8: =COUNTIF(I$4:I$15,0) -> 0 | X8: =COUNTIF(J$4:J$15,0) -> 0 | AD8: 5 | AE8: 0 | AF8: =SUM(R8:X8) -> 0 | AH8: 0
C9: Logistics Data | R9: =SUM(R4:R8) -> 0 | S9: =SUM(S4:S8) -> 0 | T9: =SUM(T4:T8) -> 0 | U9: =SUM(U4:U8) -> 0 | V9: =SUM(V4:V8) -> 0 | W9: =SUM(W4:W8) -> 0 | X9: =SUM(X4:X8) -> 0 | AD9: =SUM(AD4:AD8) -> 67 | AE9: =SUM(AE4:AE8) -> 69 | AF9: =SUM(AF4:AF8) -> 0 | AG9: 81 | AH9: =SUM(AH4:AH8) -> 81 | AI9: 81
C10: Testing & Verification
C11: Introduction to Project Management | AA11: LEVEL 2+ | AB11: Practitioner+ | AD11: =SUM(AD12:AD14) -> 0.59701493 | AE11: =SUM(AE12:AE14) -> 0.85507246 | AF11: =SUM(AF12:AF14) -> #DIV/0! | AG11: =SUM(AG12:AG14) -> 0 | AH11: =SUM(AH12:AH14) -> 0.71604938 | AI11: =SUM(AI12:AI14) -> 0
C12: Stakeholder Communication (Soft Skill ) | AA12: LEVEL-4 | AB12: Master | AD12: =AD4/$AD$9 -> 0 | AE12: =AE4/$AE$9 -> 0.028985507 | AF12: =AF4/$AF$9 -> #DIV/0! | AG12: =AG4/$AG$9 -> 0 | AH12: =AH4/$AH$9 -> 0.024691358 | AI12: =AI4/$AI$9 -> 0
C13: Articulation and ability to communicate(Presentation Skills ) | AA13: LEVEL-3 | AB13: Expert | AD13: =AD5/$AD$9 -> 0.25373134 | AE13: =AE5/$AE$9 -> 0.37681159 | AF13: =AF5/$AF$9 -> #DIV/0! | AG13: =AG5/$AG$9 -> 0 | AH13: =AH5/$AH$9 -> 0.32098765 | AI13: =AI5/$AI$9 -> 0
C14: Ownership and Accountability (Say Do Ratio) | AA14: LEVEL-2 | AB14: Practitioner | AD14: =AD6/$AD$9 -> 0.34328358 | AE14: =AE6/$AE$9 -> 0.44927536 | AF14: =AF6/$AF$9 -> #DIV/0! | AG14: =AG6/$AG$9 -> 0 | AH14: =AH6/$AH$9 -> 0.37037037 | AI14: =AI6/$AI$9 -> 0
C15: Assertiveness (Soft Skills) | AA15: LEVEL-1 | AB15: Foundation | AD15: =AD7/$AD$9 -> 0.32835821 | AE15: =AE7/$AE$9 -> 0.14492754 | AF15: =AF7/$AF$9 -> #DIV/0! | AG15: =AG7/$AG$9 -> 0 | AH15: =AH7/$AH$9 -> 0.28395062 | AI15: =AI7/$AI$9 -> 0
D16: =AVERAGE(D4:D15) -> #DIV/0! | E16: =AVERAGE(E4:E15) -> #DIV/0! | F16: =AVERAGE(F4:F15) -> #DIV/0! | G16: =AVERAGE(G4:G15) -> #DIV/0! | H16: =AVERAGE(H4:H15) -> #DIV/0! | I16: =AVERAGE(I4:I15) -> #DIV/0! | J16: =AVERAGE(J4:J15) -> #DIV/0! | AA16: LEVEL-0 | AB16: Entry | AD16: =AD8/$AD$9 -> 0.074626866 | AE16: =AE8/$AE$9 -> 0 | AF16: =AF8/$AF$9 -> #DIV/0! | AG16: =AG8/$AG$9 -> 0 | AH16: =AH8/$AH$9 -> 0 | AI16: =AI8/$AI$9 -> 0
AA17: TOTAL | AD17: =AD9/$AD$9 -> 1 | AE17: =AE9/$AE$9 -> 1 | AF17: =AF9/$AF$9 -> #DIV/0! | AG17: =AG9/$AG$9 -> 1 | AH17: =AH9/$AH$9 -> 1 | AI17: =AI9/$AI$9 -> 1
B18: First assessor | C18: Kamal | AA18: 2026 Goal | AD18: 0.86
B19: Second assessor | C19: Sjoukje's team | AA19: YTD
AA20: H1'2026 Target | AD20: =SUM(AF12:AF14) -> #DIV/0!
AA21: Gap to 2026 Goal | AD21: =AD18-AD20 -> #DIV/0!

Sheet EE-H1
B2: STET-GB Competency Assessment 2025 | D2: Electrical Engineering
B3: Function group | D3: Manasvini | E3: Shreya | F3: Mahesh | G3: Swami | H3: Pankaj | L3: =SUM(L4:L8) -> 12 | M3: =SUM(M4:M8) -> 12 | N3: =SUM(N4:N8) -> 12 | O3: =SUM(O4:O8) -> 12 | P3: =SUM(P4:P8) -> 12 | Q3: =SUM(Q4:Q8) -> 21 | R3: =SUM(R4:R8) -> 48 | S3: =SUM(S4:S8) -> 48 | ... U3: =SUM(U4:U8) -> 0
C4: Development E-process in electronic domain | D4: 0 | E4: 1 | F4: 2 | G4: 1 | H4: 0 | J4: LEVEL-4 | K4: Master | L4: =COUNTIF(D$4:D$15,4) -> 0 | M4: =COUNTIF(E$4:E$15,4) -> 0 | N4: =COUNTIF(F$4:F$15,4) -> 0 | O4: =COUNTIF(G$4:G$15,4) -> 0 | P4: =COUNTIF(H$4:H$15,4) -> 0 | Q4: 0 | R4: 0 | S4: 0 | T4: 0
C5: Doors: requirements electronics | D5: 0 | E5: 0 | F5: 1 | G5: 2 | H5: 0 | J5: LEVEL-3 | K5: Expert | L5: =COUNTIF(D$4:D$15,3) -> 0 | M5: =COUNTIF(E$4:E$15,3) -> 0 | N5: =COUNTIF(F$4:F$15,3) -> 0 | O5: =COUNTIF(G$4:G$15,3) -> 2 | P5: =COUNTIF(H$4:H$15,3) -> 0 | Q5: 0 | R5: 2 | S5: 2 | T5: 2
C6: Altium/LT spice E-CAD/mentorGraphics | D6: 0 | E6: 1 | F6: 2 | G6: 1 | H6: 0 | J6: LEVEL-2 | K6: Practitioner | L6: =COUNTIF(D$4:D$15,2) -> 1 | M6: =COUNTIF(E$4:E$15,2) -> 2 | N6: =COUNTIF(F$4:F$15,2) -> 10 | O6: =COUNTIF(G$4:G$15,2) -> 4 | P6: =COUNTIF(H$4:H$15,2) -> 0 | Q6: 12 | R6: 17 | S6: 17 | T6: 17
C7: Electrical testing /Unit Testing /Regression Testing | D7: 0 | E7: 1 | F7: 2 | G7: 2 | H7: 0 | J7: LEVEL-1 | K7: Foundation | L7: =COUNTIF(D$4:D$15,1) -> 3 | M7: =COUNTIF(E$4:E$15,1) -> 7 | N7: =COUNTIF(F$4:F$15,1) -> 2 | O7: =COUNTIF(G$4:G$15,1) -> 5 | P7: =COUNTIF(H$4:H$15,1) -> 0 | Q7: 7 | R7: 17 | S7: 17 | T7: 17
C8: design analysis | D8: 0 | E8: 1 | F8: 2 | G8: 1 | H8: 0 | J8: LEVEL-0 | K8: Entry | L8: =COUNTIF(D$4:D$15,0) -> 8 | M8: =COUNTIF(E$4:E$15,0) -> 3 | N8: =COUNTIF(F$4:F$15,0) -> 0 | O8: =COUNTIF(G$4:G$15,0) -> 1 | P8: =COUNTIF(H$4:H$15,0) -> 12 | Q8: 2 | R8: 12 | S8: 12 | T8: 24
C9: VAVE , component analysis | D9: 0 | E9: 2 | F9: 2 | G9: 1 | H9: 0 | K9: NA | L9: 0 | M9: 0 | N9: 0 | O9: 0 | P9: 0 | Q9: 1 | R9: 0 | S9: 0 | T9: 0
C10: Statistical analysis | D10: 0 | E10: 0 | F10: 1 | G10: 1 | H10: 0 | L10: =D3 -> Manasvini | M10: =E3 -> Shreya | N10: =F3 -> Mahesh | O10: =G3 -> Swami | P10: =H3 -> Pankaj | Q10: 2024 Baseline | R10: H1'25 Target | S10: H1'25 Actual | T10: H2'25 Target | U10: H2'25 Actual
C11: EMI /EMC , Environmental Testing | D11: 0 | E11: 0 | F11: 2 | G11: 0 | H11: 0
C12: Stakeholder Communication ( Soft Skills) | D12: 1 | E12: 2 | F12: 2 | G12: 2 | H12: 0 | O12: LEVEL-4 | P12: Master | Q12: =Q4/$Q$3 -> 0 | R12: =R4/$R$3 -> 0 | S12: =S4/$S$3 -> 0 | T12: =T4/$T$3 -> 0 | U12: =U4/$U$3 -> #DIV/0!
C13: Proactiveness | D13: 1 | E13: 1 | F13: 2 | G13: 3 | H13: 0 | O13: LEVEL-3 | P13: Expert | Q13: =Q5/$Q$3 -> 0 | R13: =R5/$R$3 -> 0.041666667 | S13: =S5/$S$3 -> 0.041666667 | T13: =T5/$T$3 -> 0.033333333 | U13: =U5/$U$3 -> #DIV/0!
C14: Ownership and Accountability (Say Do Ratio) | D14: 1 | E14: 1 | F14: 2 | G14: 3 | H14: 0 | O14: LEVEL-2 | P14: Practitioner | Q14: =Q6/$Q$3 -> 0.57142857 | R14: =R6/$R$3 -> 0.35416667 | S14: =S6/$S$3 -> 0.35416667 | T14: =T6/$T$3 -> 0.28333333 | U14: =U6/$U$3 -> #DIV/0!
C15: Assertiveness ( Soft Skills) | D15: 2 | E15: 1 | F15: 2 | G15: 2 | H15: 0 | O15: LEVEL-1 | P15: Foundation | Q15: =Q7/$Q$3 -> 0.33333333 | R15: =R7/$R$3 -> 0.35416667 | S15: =S7/$S$3 -> 0.35416667 | T15: =T7/$T$3 -> 0.28333333 | U15: =U7/$U$3 -> #DIV/0!
D16: =AVERAGE(D4:D15) -> 0.41666667 | E16: =AVERAGE(E4:E15) -> 0.91666667 | F16: =AVERAGE(F4:F15) -> 1.8333333 | G16: =AVERAGE(G4:G15) -> 1.5833333 | H16: =AVERAGE(H4:H15) -> 0 | O16: LEVEL-0 | P16: Entry | Q16: =Q8/$Q$3 -> 0.095238095 | R16: =R8/$R$3 -> 0.25 | S16: =S8/$S$3 -> 0.25 | T16: =T8/$T$3 -> 0.4 | U16: =U8/$U$3 -> #DIV/0!
O17: TOTAL | Q17: =SUM(Q12:Q16) -> 1 | R17: =SUM(R12:R16) -> 1 | S17: =SUM(S12:S16) -> 1 | T17: =SUM(T12:T16) -> 1 | U17: =SUM(U12:U16) -> #DIV/0!
B18: First assessor | C18: Dayal | O18: 2025 Goal | Q18: 0.65
B19: Second assessor | C19: Martin | O19: YTD | Q19: =S12+S13+S14 -> 0.39583333
O20: H2'2025 Target | Q20: =SUM(T12:T14) -> 0.31666667
O21: Gap to Goal | Q21: =Q19-Q18 -> -0.25416667

Sheet EE
B2: STET-GB Competency Assessment 2026 | D2: Electrical Engineers
D3: Manasvini | E3: Shreya | F3: Mahesh | G3: 584652 | H3: Pankaj | I3: Raghu | S3: =D3 -> Manasvini | T3: =E3 -> Shreya | U3: =F3 -> Mahesh | V3: =G3 -> 584652 | W3: =H3 -> Pankaj | X3: =I3 -> Raghu | Y3: =J3 -> 0 | Z3: =K3 -> 0 | ... AD3: =O3 -> 0 | AE3: 2024 Baseline | AF3: 2025 Baseline | AG3: H1'26 Target | AH3: H1'26 Actual | AI3: H2'26 Target | AJ3: H2'26 Actual
C4: Development E-process in electronic domain | D4: 1 | E4: 2 | F4: 3 | G4: 1 | H4: 2 | I4: 3 | Q4: LEVEL-4 | R4: Master | Z4: =COUNTIF(K$4:K$15,4) -> 0 | AA4: =COUNTIF(L$4:L$15,4) -> 0 | AB4: =COUNTIF(M$4:M$15,4) -> 0 | AC4: =COUNTIF(N$4:N$15,4) -> 0 | AD4: =COUNTIF(O$4:O$15,4) -> 0 | AE4: 0 | AF4: 0 | AG4: =SUM(S4:W4) -> 0 | AI4: 0
C5: Doors: requirements electronics | D5: 0 | E5: 1 | F5: 2 | G5: 0 | H5: 2 | I5: 2 | Q5: LEVEL-3 | R5: Expert | Z5: =COUNTIF(K$4:K$15,3) -> 0 | AA5: =COUNTIF(L$4:L$15,3) -> 0 | AB5: =COUNTIF(M$4:M$15,3) -> 0 | AC5: =COUNTIF(N$4:N$15,3) -> 0 | AD5: =COUNTIF(O$4:O$15,3) -> 0 | AE5: 0 | AF5: 1 | AG5: =SUM(S5:W5) -> 0 | AI5: 7
C6: Altium/LT spice E-CAD/mentorGraphics | D6: 1 | E6: 2 | F6: 2 | G6: 1 | H6: 2 | I6: 2 | Q6: LEVEL-2 | R6: Practitioner | Z6: =COUNTIF(K$4:K$15,2) -> 0 | AA6: =COUNTIF(L$4:L$15,2) -> 0 | AB6: =COUNTIF(M$4:M$15,2) -> 0 | AC6: =COUNTIF(N$4:N$15,2) -> 0 | AD6: =COUNTIF(O$4:O$15,2) -> 0 | AE6: 12 | AF6: 24 | AG6: =SUM(S6:W6) -> 0 | AI6: 30
C7: Electrical testing /Unit Testing /Regression Testing | D7: 0 | E7: 2 | F7: 3 | G7: 2 | H7: 3 | I7: 3 | Q7: LEVEL-1 | R7: Foundation | Z7: =COUNTIF(K$4:K$15,1) -> 0 | AA7: =COUNTIF(L$4:L$15,1) -> 0 | AB7: =COUNTIF(M$4:M$15,1) -> 0 | AC7: =COUNTIF(N$4:N$15,1) -> 0 | AD7: =COUNTIF(O$4:O$15,1) -> 0 | AE7: 7 | AF7: 11 | AG7: =SUM(S7:W7) -> 0 | AI7: 7
C8: design analysis | D8: 1 | E8: 2 | F8: 3 | G8: 2 | H8: 3 | I8: 3 | Q8: LEVEL-0 | R8: Entry | Z8: =COUNTIF(K$4:K$15,0) -> 0 | AA8: =COUNTIF(L$4:L$15,0) -> 0 | AB8: =COUNTIF(M$4:M$15,0) -> 0 | AC8: =COUNTIF(N$4:N$15,0) -> 0 | AD8: =COUNTIF(O$4:O$15,0) -> 0 | AE8: 2 | AF8: 12 | AG8: =SUM(S8:W8) -> 0 | AI8: 4
C9: VAVE , component analysis | D9: 2 | E9: 2 | F9: 2 | G9: 2 | H9: 2 | I9: 2 | S9: =SUM(S4:S8) -> 0 | T9: =SUM(T4:T8) -> 0 | U9: =SUM(U4:U8) -> 0 | V9: =SUM(V4:V8) -> 0 | W9: =SUM(W4:W8) -> 0 | X9: =SUM(X4:X8) -> 0 | Y9: =SUM(Y4:Y8) -> 0 | Z9: =SUM(Z4:Z8) -> 0 | ... AG9: =SUM(AG4:AG8) -> 0 | AH9: 48 | AI9: =SUM(AI4:AI8) -> 48 | AJ9: 48
C10: Statistical analysis | D10: 0 | E10: 1 | F10: 1 | G10: 1 | H10: 2 | I10: 2
C11: EMI /EMC , Environmental Testing | D11: 0 | E11: 1 | F11: 2 | G11: 0 | H11: 2 | I11: 1 | AB11: LEVEL 2+ | AC11: Practitioner+ | AE11: =SUM(AE12:AE14) -> 0.57142857 | AF11: =SUM(AF12:AF14) -> 0.52083333 | AG11: =SUM(AG12:AG14) -> #DIV/0! | AH11: =SUM(AH12:AH14) -> 0 | AI11: =SUM(AI12:AI14) -> 0.77083333 | AJ11: =SUM(AJ12:AJ14) -> 0
C12: Stakeholder Communication ( Soft Skills) | D12: 2 | E12: 2 | F12: 2 | G12: 2 | H12: 2 | I12: 2 | AB12: LEVEL-4 | AC12: Master | AE12: =AE4/$AE$9 -> 0 | AF12: =AF4/$AF$9 -> 0 | AG12: =AG4/$AG$9 -> #DIV/0! | AH12: =AH4/$AH$9 -> 0 | AI12: =AI4/$AI$9 -> 0 | AJ12: =AJ4/$AJ$9 -> 0
C13: Proactiveness | D13: 2 | E13: 2 | F13: 3 | G13: 2 | H13: 2 | I13: 2 | AB13: LEVEL-3 | AC13: Expert | AE13: =AE5/$AE$9 -> 0 | AF13: =AF5/$AF$9 -> 0.020833333 | AG13: =AG5/$AG$9 -> #DIV/0! | AH13: =AH5/$AH$9 -> 0 | AI13: =AI5/$AI$9 -> 0.14583333 | AJ13: =AJ5/$AJ$9 -> 0
C14: Ownership and Accountability (Say Do Ratio) | D14: 2 | E14: 2 | F14: 3 | G14: 2 | H14: 2 | I14: 2 | AB14: LEVEL-2 | AC14: Practitioner | AE14: =AE6/$AE$9 -> 0.57142857 | AF14: =AF6/$AF$9 -> 0.5 | AG14: =AG6/$AG$9 -> #DIV/0! | AH14: =AH6/$AH$9 -> 0 | AI14: =AI6/$AI$9 -> 0.625 | AJ14: =AJ6/$AJ$9 -> 0
C15: Assertiveness ( Soft Skills) | D15: 2 | E15: 2 | F15: 2 | G15: 2 | H15: 2 | I15: 2 | AB15: LEVEL-1 | AC15: Foundation | AE15: =AE7/$AE$9 -> 0.33333333 | AF15: =AF7/$AF$9 -> 0.22916667 | AG15: =AG7/$AG$9 -> #DIV/0! | AH15: =AH7/$AH$9 -> 0 | AI15: =AI7/$AI$9 -> 0.14583333 | AJ15: =AJ7/$AJ$9 -> 0
D16: =AVERAGE(D4:D15) -> 1.0833333 | E16: =AVERAGE(E4:E15) -> 1.75 | F16: =AVERAGE(F4:F15) -> 2.3333333 | G16: =AVERAGE(G4:G15) -> 1.4166667 | H16: =AVERAGE(H4:H15) -> 2.1666667 | I16: 2.2 | AB16: LEVEL-0 | AC16: Entry | AE16: =AE8/$AE$9 -> 0.095238095 | AF16: =AF8/$AF$9 -> 0.25 | AG16: =AG8/$AG$9 -> #DIV/0! | AH16: =AH8/$AH$9 -> 0 | AI16: =AI8/$AI$9 -> 0.083333333 | AJ16: =AJ8/$AJ$9 -> 0
AB17: TOTAL | AE17: =AE9/$AE$9 -> 1 | AF17: =AF9/$AF$9 -> 1 | AG17: =AG9/$AG$9 -> #DIV/0! | AH17: =AH9/$AH$9 -> 1 | AI17: =AI9/$AI$9 -> 1 | AJ17: =AJ9/$AJ$9 -> 1
B18: First assessor | C18: Dayal | AB18: 2026 Goal | AE18: 0.7
B19: Second assessor | C19: Martin | AB19: YTD
AB20: H1'2026 Target | AE20: =SUM(AG12:AG14) -> #DIV/0!
AB21: Gap to 2026 Goal | AE21: =AE18-AE20 -> #DIV/0!

Sheet QPL
B2: STET-GB Competency Assessment 2026 | D2: Quality Project Leaders
C3: Basic functional training | D3: Kevin | E3: Vivek | F3: Mahaveer | G3: Vinayak | H3: Subhash | I3: Akash | J3: Dinesh | K3: Rutuja | L3: 578622 | S3: =D3 -> Kevin | T3: =E3 -> Vivek | U3: =F3 -> Mahaveer | V3: =G3 -> Vinayak | W3: =H3 -> Subhash | X3: =I3 -> Akash | Y3: =J3 -> Dinesh | Z3: =K3 -> Rutuja | ... AD3: =O3 -> 0 | AE3: 2024 Baseline | AF3: 2025 Baseline | AG3: H1'26 Target | AH3: H1'26 Actual | AI3: H2'26 Target | AJ3: H2'26 Actual
C4: Medical Standards & Regulatory Compliance (Design Controls) | L4: 0 | Q4: LEVEL-4 | R4: Master | S4: =COUNTIF(D$4:D$17,4) -> 0 | T4: =COUNTIF(E$4:E$17,4) -> 0 | U4: =COUNTIF(F$4:F$17,4) -> 0 | V4: =COUNTIF(G$4:G$17,4) -> 0 | W4: =COUNTIF(H$4:H$17,4) -> 0 | X4: =COUNTIF(I$4:I$17,4) -> 0 | Y4: =COUNTIF(J$4:J$17,4) -> 0 | Z4: =COUNTIF(K$4:K$17,4) -> 0 | ... AD4: =COUNTIF(O$4:O$17,4) -> 0 | AE4: 0 | AF4: 0 | AG4: 0 | AI4: 0
C5: MLD/LCM Process knowledge and adherence | L5: 0 | Q5: LEVEL-3 | R5: Expert | S5: =COUNTIF(D$4:D$17,3) -> 0 | T5: =COUNTIF(E$4:E$17,3) -> 0 | U5: =COUNTIF(F$4:F$17,3) -> 0 | V5: =COUNTIF(G$4:G$17,3) -> 0 | W5: =COUNTIF(H$4:H$17,3) -> 0 | X5: =COUNTIF(I$4:I$17,3) -> 0 | Y5: =COUNTIF(J$4:J$17,3) -> 0 | Z5: =COUNTIF(K$4:K$17,3) -> 0 | ... AD5: =COUNTIF(O$4:O$17,3) -> 0 | AE5: 0 | AF5: 0 | AG5: 8 | AI5: 11
C6: Product/Portfolio knowledge | L6: 0 | Q6: LEVEL-2 | R6: Practitioner | S6: =COUNTIF(D$4:D$17,2) -> 0 | T6: =COUNTIF(E$4:E$17,2) -> 0 | U6: =COUNTIF(F$4:F$17,2) -> 0 | V6: =COUNTIF(G$4:G$17,2) -> 0 | W6: =COUNTIF(H$4:H$17,2) -> 0 | X6: =COUNTIF(I$4:I$17,2) -> 0 | Y6: =COUNTIF(J$4:J$17,2) -> 0 | Z6: =COUNTIF(K$4:K$17,2) -> 0 | ... AD6: =COUNTIF(O$4:O$17,2) -> 0 | AE6: 6 | AF6: 34 | AG6: 39 | AI6: 50
C7: Problem Solving : Shainin/DFSS/DMAIC/8D/RCA/CAPA (Via PMS/PQR's) | L7: 0 | Q7: LEVEL-1 | R7: Foundation | S7: =COUNTIF(D$4:D$17,1) -> 0 | T7: =COUNTIF(E$4:E$17,1) -> 0 | U7: =COUNTIF(F$4:F$17,1) -> 0 | V7: =COUNTIF(G$4:G$17,1) -> 0 | W7: =COUNTIF(H$4:H$17,1) -> 0 | X7: =COUNTIF(I$4:I$17,1) -> 0 | Y7: =COUNTIF(J$4:J$17,1) -> 0 | Z7: =COUNTIF(K$4:K$17,1) -> 0 | ... AD7: =COUNTIF(O$4:O$17,1) -> 0 | AE7: 1 | AF7: 29 | AG7: 36 | AI7: 32
C8: Stakeholder Communication (Soft Skill ) | L8: 0 | Q8: LEVEL-0 | R8: Entry | S8: =COUNTIF(D$4:D$17,0) -> 0 | T8: =COUNTIF(E$4:E$17,0) -> 0 | U8: =COUNTIF(F$4:F$17,0) -> 0 | V8: =COUNTIF(G$4:G$17,0) -> 0 | W8: =COUNTIF(H$4:H$17,0) -> 0 | X8: =COUNTIF(I$4:I$17,0) -> 0 | Y8: =COUNTIF(J$4:J$17,0) -> 0 | Z8: =COUNTIF(K$4:K$17,0) -> 0 | ... AD8: =COUNTIF(O$4:O$17,0) -> 0 | AE8: 9 | AF8: 3 | AG8: 0 | AI8: 0
C9: Ownership and Accountability (Say Do Ratio) | L9: 0 | S9: =SUM(S4:S8) -> 0 | T9: =SUM(T4:T8) -> 0 | U9: =SUM(U4:U8) -> 0 | V9: =SUM(V4:V8) -> 0 | W9: =SUM(W4:W8) -> 0 | X9: =SUM(X4:X8) -> 0 | Y9: =SUM(Y4:Y8) -> 0 | Z9: =SUM(Z4:Z8) -> 0 | ... AG9: =SUM(AG4:AG8) -> 83 | AH9: 83 | AI9: =SUM(AI4:AI8) -> 93 | AJ9: 93
C10: Philisp RSL and sustainability requirements understanding | L10: 0
C11: Sustainability Data management (Contains: MaxBom/Categorization, tech files update, France Agec, EU SCIP) | L11: 0 | AB11: LEVEL 2+ | AC11: Practitioner+ | AE11: =SUM(AE12:AE14) -> 0.375 | AF11: =SUM(AF12:AF14) -> 0.51515152 | AG11: =SUM(AG12:AG14) -> 0.56626506 | AH11: =SUM(AH12:AH14) -> 0 | AI11: =SUM(AI12:AI14) -> 0.65591398 | AJ11: =SUM(AJ12:AJ14) -> 0
C12: Effective usage of LCM Tools for QPL role and documentation (Includes: Windchill, Bomcheck, RTC, Aris, Vertex, Bomcheck, tech files, Qlikview) | L12: 0 | AB12: LEVEL-4 | AC12: Master | AE12: =AE4/$AE$9 -> 0 | AF12: =AF4/$AF$9 -> 0 | AG12: =AG4/$AG$9 -> 0 | AH12: =AH4/$AH$9 -> 0 | AI12: =AI4/$AI$9 -> 0 | AJ12: =AJ4/$AJ$9 -> 0
C13: Gap analysis & change mahangement(IA, RfS execution, Completeness, RSL gaps) | L13: 0 | AB13: LEVEL-3 | AC13: Expert | AE13: =AE5/$AE$9 -> 0 | AF13: =AF5/$AF$9 -> 0 | AG13: =AG5/$AG$9 -> 0.096385542 | AH13: =AH5/$AH$9 -> 0 | AI13: =AI5/$AI$9 -> 0.11827957 | AJ13: =AJ5/$AJ$9 -> 0
C14: Risk management (HBSRA+RMM) | L14: 0 | AB14: LEVEL-2 | AC14: Practitioner | AE14: =AE6/$AE$9 -> 0.375 | AF14: =AF6/$AF$9 -> 0.51515152 | AG14: =AG6/$AG$9 -> 0.46987952 | AH14: =AH6/$AH$9 -> 0 | AI14: =AI6/$AI$9 -> 0.53763441 | AJ14: =AJ6/$AJ$9 -> 0
C15: Reg-Mem management (Scope+Execution) | L15: 0 | AB15: LEVEL-1 | AC15: Foundation | AE15: =AE7/$AE$9 -> 0.0625 | AF15: =AF7/$AF$9 -> 0.43939394 | AG15: =AG7/$AG$9 -> 0.43373494 | AH15: =AH7/$AH$9 -> 0 | AI15: =AI7/$AI$9 -> 0.34408602 | AJ15: =AJ7/$AJ$9 -> 0
C16: Influencing Skills/Decision making (Soft Skill ) | L16: 0 | AB16: LEVEL-0 | AC16: Entry | AE16: =AE8/$AE$9 -> 0.5625 | AF16: =AF8/$AF$9 -> 0.045454545 | AG16: =AG8/$AG$9 -> 0 | AH16: =AH8/$AH$9 -> 0 | AI16: =AI8/$AI$9 -> 0 | AJ16: =AJ8/$AJ$9 -> 0
C17: Creation/review/Approval of Quality documentation (Includes: Labeling, AW's, Test design and reports, HSD, Waviers, Lab Transfer, PDLM deliverables) | L17: 0 | AB17: TOTAL | AE17: =AE9/$AE$9 -> 1 | AF17: =AF9/$AF$9 -> 1 | AG17: =AG9/$AG$9 -> 1 | AH17: =AH9/$AH$9 -> 1 | AI17: =AI9/$AI$9 -> 1 | AJ17: =AJ9/$AJ$9 -> 1
D18: =AVERAGE(D4:D17) -> #DIV/0! | E18: =AVERAGE(E4:E17) -> #DIV/0! | F18: =AVERAGE(F4:F17) -> #DIV/0! | G18: =AVERAGE(G4:G17) -> #DIV/0! | H18: =AVERAGE(H4:H17) -> #DIV/0! | I18: =AVERAGE(I4:I17) -> #DIV/0! | J18: =AVERAGE(J4:J17) -> #DIV/0! | K18: =AVERAGE(K4:K17) -> #DIV/0! | L18: =AVERAGE(L4:L17) -> 0 | AB18: 2026 Goal | AE18: 0.7
AB19: YTD
B20: First assessor | C20: Sonam Nikam | AB20: H1'2026 Target | AE20: =SUM(AG12:AG14) -> 0.56626506
B21: Second assessor | C21: Jim Timmermans/Erik Stap | AB21: Gap to 2026 Goal | AE21: =AE18-AE20 -> 0.13373494

Sheet SE
B2: STET-GB Competency Assessment 2026 | D2: System Engineers
D3: Mrunal | E3: Rajkumar | F3: Kirti | G3: Vinay | H3: Madhuri | I3: Kola | J3: Bindu | K3: Avani | S3: =D3 -> Mrunal | T3: =E3 -> Rajkumar | U3: =F3 -> Kirti | V3: =G3 -> Vinay | W3: =H3 -> Madhuri | X3: =I3 -> Kola | Y3: =J3 -> Bindu | Z3: =K3 -> Avani | ... AD3: =O3 -> 0 | AE3: 2024 Baseline | AF3: 2025 Baseline | AG3: H1'26 Target | AH3: H1'26 Actual | AI3: H2'26 Target | AJ3: H2'26 Actual
B4: Technical Trainings | C4: Technical root cause analysis | Q4: LEVEL-4 | R4: Master | S4: =COUNTIF(D$4:D$19,4) -> 0 | T4: =COUNTIF(E$4:E$19,4) -> 0 | U4: =COUNTIF(F$4:F$19,4) -> 0 | V4: =COUNTIF(G$4:G$19,4) -> 0 | W4: =COUNTIF(H$4:H$19,4) -> 0 | X4: =COUNTIF(I$4:I$19,4) -> 0 | Y4: =COUNTIF(J$4:J$19,4) -> 0 | Z4: =COUNTIF(K$4:K$19,4) -> 0 | ... AD4: =COUNTIF(O$4:O$19,4) -> 0 | AE4: 0 | AF4: 0 | AG4: 8 | AI4: 8
C5: Technical problem solving | Q5: LEVEL-3 | R5: Expert | S5: =COUNTIF(D$4:D$19,3) -> 0 | T5: =COUNTIF(E$4:E$19,3) -> 0 | U5: =COUNTIF(F$4:F$19,3) -> 0 | V5: =COUNTIF(G$4:G$19,3) -> 0 | W5: =COUNTIF(H$4:H$19,3) -> 0 | X5: =COUNTIF(I$4:I$19,3) -> 0 | Y5: =COUNTIF(J$4:J$19,3) -> 0 | Z5: =COUNTIF(K$4:K$19,3) -> 0 | ... AD5: =COUNTIF(O$4:O$19,3) -> 0 | AE5: 0 | AF5: 1 | AG5: 47 | AI5: 47
